Workbook

Sheet Raw data
A1: Order ID | B1: Date | C1: Customer Name | D1: Product | E1: Category | F1: Quantity | G1: Unit price | H1: Discount% | I1: Payment method
A2: ORD001 | B2: 46235 | C2: Rahul sharma | D2: Laptop | E2: Electronics | F2: 2 | G2: 45000 | H2: 0.1 | I2: UPI
A3: ORD002 | B3: 46236 | C3: Priya verma | D3: Shoes | E3: Fashion | F3: 1 | G3: 2500 | H3: 0.05 | I3: Card
A4: ORD003 | B4: 46237 | C4: Amit kumar | D4: Smartphone | E4: Electronics | F4: 1 | G4: 28000 | H4: 0.08 | I4: UPI
A5: ORD004 | B5: 46238 | C5: Neha singh | D5: Tshirt | E5: Fashion | F5: 3 | G5: 800 | H5: 0.1 | I5: Cash
A6: ORD005 | B6: 46239 | C6: Ananya gupta | D6: Headphones | E6: Electronics | F6: 2 | G6: 2200 | H6: 0.05 | I6: UPI
A7: ORD006 | B7: 46240 | C7: Rohan mehta | D7: Bagpack | E7: Accessories | F7: 2 | G7: 1800 | H7: 0.1 | I7: Card
A8: ORD007 | B8: 46241 | C8: Sneha yadav | D8: Tablet | E8: Electronics | F8: 1 | G8: 22000 | H8: 0.12 | I8: UPI
A9: ORD008 | B9: 46242 | C9: Arjun Malhotra | D9: Jeans | E9: Fashion | F9: 2 | G9: 1800 | H9: 0.05 | I9: Card
A10: ORD009 | B10: 46243 | C10: Pooja mishra | D10: Keyboard | E10: Electronics | F10: 3 | G10: 1500 | H10: 0.08 | I10: UPI
A11: ORD010 | B11: 46244 | C11: Karan Joshi | D11: Watch | E11: Accessories | F11: 1 | G11: 3500 | H11: 0.1 | I11: cash
A12: ORD011 | B12: 46245 | C12: Rahul sharma | D12: Monitor | E12: Electronics | F12: 2 | G12: 12000 | H12: 0.15 | I12: Card
A13: ORD012 | B13: 46246 | C13: Priya verma | D13: Saree | E13: Fashion | F13: 1 | G13: 3200 | H13: 0.05 | I13: UPI
... A51: ORD050 | B51: 46284 | C51: Karan Joshi | D51: Watch | E51: Accessories | F51: 2 | G51: 3800 | H51: 0.08 | I51: Card

Sheet Clean Data
A1: Order ID | B1: Date | C1: Customer Name | D1: Product | E1: Category | F1: Quantity | G1: Unit price | H1: Discount% | I1: Payment method | J1: Duplicate check | K1: Missing check | L1: Data quality check | M1: Salesperson | N1: Net sales
A2: ORD001 | B2: 46235 | C2: Rahul sharma | D2: Laptop | E2: Electronics | F2: 2 | G2: 45000 | H2: 0.1 | I2: UPI | J2: =IF(COUNTIF($A$2:$A$51,A2)>1,"Duplicate","Unique") -> Unique | K2: =IF(COUNTA(A2:I2)<9,"Missing Data","Complete") -> Complete | L2: =IF(AND(F2>0,G2>0,H2>=0,H2<=100),"Valid","Check") -> Valid | M2: Rahul | N2: =F2*G2*(1-H2) -> 81000
A3: ORD002 | B3: 46236 | C3: Priya verma | D3: Shoes | E3: Fashion | F3: 1 | G3: 2500 | H3: 0.05 | I3: Card | J3: =IF(COUNTIF($A$2:$A$51,A3)>1,"Duplicate","Unique") -> Unique | K3: =IF(COUNTA(A3:I3)<9,"Missing Data","Complete") -> Complete | L3: =IF(AND(F3>0,G3>0,H3>=0,H3<=100),"Valid","Check") -> Valid | M3: Priya | N3: =F3*G3*(1-H3) -> 2375
A4: ORD003 | B4: 46237 | C4: Amit kumar | D4: Smartphone | E4: Electronics | F4: 1 | G4: 28000 | H4: 0.08 | I4: UPI | J4: =IF(COUNTIF($A$2:$A$51,A4)>1,"Duplicate","Unique") -> Unique | K4: =IF(COUNTA(A4:I4)<9,"Missing Data","Complete") -> Complete | L4: =IF(AND(F4>0,G4>0,H4>=0,H4<=100),"Valid","Check") -> Valid | M4: Amit | N4: =F4*G4*(1-H4) -> 25760
A5: ORD004 | B5: 46238 | C5: Neha singh | D5: Tshirt | E5: Fashion | F5: 3 | G5: 800 | H5: 0.1 | I5: Cash | J5: =IF(COUNTIF($A$2:$A$51,A5)>1,"Duplicate","Unique") -> Unique | K5: =IF(COUNTA(A5:I5)<9,"Missing Data","Complete") -> Complete | L5: =IF(AND(F5>0,G5>0,H5>=0,H5<=100),"Valid","Check") -> Valid | M5: Neha | N5: =F5*G5*(1-H5) -> 2160
A6: ORD005 | B6: 46239 | C6: Ananya gupta | D6: Headphones | E6: Electronics | F6: 2 | G6: 2200 | H6: 0.05 | I6: UPI | J6: =IF(COUNTIF($A$2:$A$51,A6)>1,"Duplicate","Unique") -> Unique | K6: =IF(COUNTA(A6:I6)<9,"Missing Data","Complete") -> Complete | L6: =IF(AND(F6>0,G6>0,H6>=0,H6<=100),"Valid","Check") -> Valid | M6: Rahul | N6: =F6*G6*(1-H6) -> 4180
A7: ORD006 | B7: 46240 | C7: Rohan mehta | D7: Bagpack | E7: Accessories | F7: 2 | G7: 1800 | H7: 0.1 | I7: Card | J7: =IF(COUNTIF($A$2:$A$51,A7)>1,"Duplicate","Unique") -> Unique | K7: =IF(COUNTA(A7:I7)<9,"Missing Data","Complete") -> Complete | L7: =IF(AND(F7>0,G7>0,H7>=0,H7<=100),"Valid","Check") -> Valid | M7: Priya | N7: =F7*G7*(1-H7) -> 3240
A8: ORD007 | B8: 46241 | C8: Sneha yadav | D8: Tablet | E8: Electronics | F8: 1 | G8: 22000 | H8: 0.12 | I8: UPI | J8: =IF(COUNTIF($A$2:$A$51,A8)>1,"Duplicate","Unique") -> Unique | K8: =IF(COUNTA(A8:I8)<9,"Missing Data","Complete") -> Complete | L8: =IF(AND(F8>0,G8>0,H8>=0,H8<=100),"Valid","Check") -> Valid | M8: Amit | N8: =F8*G8*(1-H8) -> 19360
A9: ORD008 | B9: 46242 | C9: Arjun Malhotra | D9: Jeans | E9: Fashion | F9: 2 | G9: 1800 | H9: 0.05 | I9: Card | J9: =IF(COUNTIF($A$2:$A$51,A9)>1,"Duplicate","Unique") -> Unique | K9: =IF(COUNTA(A9:I9)<9,"Missing Data","Complete") -> Complete | L9: =IF(AND(F9>0,G9>0,H9>=0,H9<=100),"Valid","Check") -> Valid | M9: Neha | N9: =F9*G9*(1-H9) -> 3420
A10: ORD009 | B10: 46243 | C10: Pooja mishra | D10: Keyboard | E10: Electronics | F10: 3 | G10: 1500 | H10: 0.08 | I10: UPI | J10: =IF(COUNTIF($A$2:$A$51,A10)>1,"Duplicate","Unique") -> Unique | K10: =IF(COUNTA(A10:I10)<9,"Missing Data","Complete") -> Complete | L10: =IF(AND(F10>0,G10>0,H10>=0,H10<=100),"Valid","Check") -> Valid | M10: Rahul | N10: =F10*G10*(1-H10) -> 4140
A11: ORD010 | B11: 46244 | C11: Karan Joshi | D11: Watch | E11: Accessories | F11: 1 | G11: 3500 | H11: 0.1 | I11: cash | J11: =IF(COUNTIF($A$2:$A$51,A11)>1,"Duplicate","Unique") -> Unique | K11: =IF(COUNTA(A11:I11)<9,"Missing Data","Complete") -> Complete | L11: =IF(AND(F11>0,G11>0,H11>=0,H11<=100),"Valid","Check") -> Valid | M11: Priya | N11: =F11*G11*(1-H11) -> 3150
A12: ORD011 | B12: 46245 | C12: Rahul sharma | D12: Monitor | E12: Electronics | F12: 2 | G12: 12000 | H12: 0.15 | I12: Card | J12: =IF(COUNTIF($A$2:$A$51,A12)>1,"Duplicate","Unique") -> Unique | K12: =IF(COUNTA(A12:I12)<9,"Missing Data","Complete") -> Complete | L12: =IF(AND(F12>0,G12>0,H12>=0,H12<=100),"Valid","Check") -> Valid | M12: Amit | N12: =F12*G12*(1-H12) -> 20400
A13: ORD012 | B13: 46246 | C13: Priya verma | D13: Saree | E13: Fashion | F13: 1 | G13: 3200 | H13: 0.05 | I13: UPI | J13: =IF(COUNTIF($A$2:$A$51,A13)>1,"Duplicate","Unique") -> Unique | K13: =IF(COUNTA(A13:I13)<9,"Missing Data","Complete") -> Complete | L13: =IF(AND(F13>0,G13>0,H13>=0,H13<=100),"Valid","Check") -> Valid | M13: Neha | N13: =F13*G13*(1-H13) -> 3040
... A51: ORD050 | B51: 46284 | C51: Karan Joshi | D51: Watch | E51: Accessories | F51: 2 | G51: 3800 | H51: 0.08 | I51: Card | J51: =IF(COUNTIF($A$2:$A$51,A51)>1,"Duplicate","Unique") -> Unique | K51: =IF(COUNTA(A51:I51)<9,"Missing Data","Complete") -> Complete | L51: =IF(AND(F51>0,G51>0,H51>=0,H51<=100),"Valid","Check") -> Valid | M51: Priya | N51: =F51*G51*(1-H51) -> 6992

Sheet Summary 
B3: ANALYSIS
A6: Metric | B6: Result
A7: Total orders | B7: =COUNTA('Clean Data'!A2:A51) -> 50
A8: Total quantity sold | B8: =SUM('Clean Data'!F2:F51) -> 106
A9: Gross sales | B9: =SUMPRODUCT('Clean Data'!F2:F51,'Clean Data'!G2:G51) -> 760150
A10: Total discount | B10: =SUMPRODUCT('Clean Data'!F2:F51,'Clean Data'!G2:G51,'Clean Data'!H2:H51) -> 83886.5
A11: Net sales | B11: =B9-B10 -> 676263.5
A12: Average order value | B12: =B11/B7 -> 13525.27
A13: Highest Sale | B13: {=MAX('Clean Data'!F2:F51*'Clean Data'!G2:G51*(1-'Clean Data'!H2:H51))} -> 81000
A14: Lowest sale | B14: {=MIN('Clean Data'!F2:F51*'Clean Data'!G2:G51*(1-'Clean Data'!H2:H51))} -> 2160
A18: SALESPERSON ANALYSIS
A20: Salesperson | B20: Total sales | C20: Orders | D20: Quantity sold
A21: Rahul | B21: =SUMIF('Clean Data'!M2:M51,A21,'Clean Data'!N2:N51) -> 331915 | C21: =COUNTIF('Clean Data'!M2:M51,A21) -> 13 | D21: =SUMIF('Clean Data'!M2:M51,A21,'Clean Data'!F2:F51) -> 28
A22: Priya | B22: =SUMIF('Clean Data'!M3:M52,A22,'Clean Data'!N3:N52) -> 57386 | C22: =COUNTIF('Clean Data'!M3:M52,A22) -> 13 | D22: =SUMIF('Clean Data'!M3:M52,A22,'Clean Data'!F3:F52) -> 28
A23: Amit | B23: =SUMIF('Clean Data'!M4:M53,A23,'Clean Data'!N4:N53) -> 235274 | C23: =COUNTIF('Clean Data'!M4:M53,A23) -> 12 | D23: =SUMIF('Clean Data'!M4:M53,A23,'Clean Data'!F4:F53) -> 25
A24: Neha | B24: =SUMIF('Clean Data'!M5:M54,A24,'Clean Data'!N5:N54) -> 51688.5 | C24: =COUNTIF('Clean Data'!M5:M54,A24) -> 12 | D24: =SUMIF('Clean Data'!M5:M54,A24,'Clean Data'!F5:F54) -> 25
A28: CATEGORY ANALYSIS
A30: Category | B30: Total sales | C30: Orders | D30: Quantity sold
A31: Electronics | B31: =SUMIF('Clean Data'!E2:E51,A31,'Clean Data'!N2:N51) -> 567189 | C31: =COUNTIF('Clean Data'!E2:E51,A31) -> 25 | D31: =SUMIF('Clean Data'!E2:E51,A31,'Clean Data'!F2:F51) -> 53
A32: Fashion | B32: =SUMIF('Clean Data'!E3:E52,A32,'Clean Data'!N3:N52) -> 69960 | C32: =COUNTIF('Clean Data'!E3:E52,A32) -> 16 | D32: =SUMIF('Clean Data'!E3:E52,A32,'Clean Data'!F3:F52) -> 35
A33: Accessories | B33: =SUMIF('Clean Data'!E4:E53,A33,'Clean Data'!N4:N53) -> 36692 | C33: =COUNTIF('Clean Data'!E4:E53,A33) -> 8 | D33: =SUMIF('Clean Data'!E4:E53,A33,'Clean Data'!F4:F53) -> 15
A36: PRODUCT ANALYSIS
A38: Product | B38: Total sales | C38: Orders | D38: Quantity sold
A39: Laptop | B39: =SUMIF('Clean Data'!D2:D51,A39,'Clean Data'!N2:N51) -> 216800 | C39: =COUNTIF('Clean Data'!D2:D51,A39) -> 4 | D39: =SUMIF('Clean Data'!D2:D51,A39,'Clean Data'!F2:F51) -> 5
A40: Smartphone | B40: =SUMIF('Clean Data'!D3:D52,A40,'Clean Data'!N3:N52) -> 131610 | C40: =COUNTIF('Clean Data'!D3:D52,A40) -> 4 | D40: =SUMIF('Clean Data'!D3:D52,A40,'Clean Data'!F3:F52) -> 5
A41: Tablet | B41: =SUMIF('Clean Data'!D4:D53,A41,'Clean Data'!N4:N53) -> 118000 | C41: =COUNTIF('Clean Data'!D4:D53,A41) -> 4 | D41: =SUMIF('Clean Data'!D4:D53,A41,'Clean Data'!F4:F53) -> 6
A42: Headphones | B42: =SUMIF('Clean Data'!D5:D54,A42,'Clean Data'!N5:N54) -> 19670 | C42: =COUNTIF('Clean Data'!D5:D54,A42) -> 3 | D42: =SUMIF('Clean Data'!D5:D54,A42,'Clean Data'!F5:F54) -> 9
A43: Keyboard | B43: =SUMIF('Clean Data'!D6:D55,A43,'Clean Data'!N6:N55) -> 13450 | C43: =COUNTIF('Clean Data'!D6:D55,A43) -> 3 | D43: =SUMIF('Clean Data'!D6:D55,A43,'Clean Data'!F6:F55) -> 9
A44: Monitor | B44: =SUMIF('Clean Data'!D7:D56,A44,'Clean Data'!N7:N56) -> 55320 | C44: =COUNTIF('Clean Data'!D7:D56,A44) -> 3 | D44: =SUMIF('Clean Data'!D7:D56,A44,'Clean Data'!F7:F56) -> 5
A45: Jacket | B45: =SUMIF('Clean Data'!D8:D57,A45,'Clean Data'!N8:N57) -> 8280 | C45: =COUNTIF('Clean Data'!D8:D57,A45) -> 2 | D45: =SUMIF('Clean Data'!D8:D57,A45,'Clean Data'!F8:F57) -> 2
A46: Shoes | B46: =SUMIF('Clean Data'!D9:D58,A46,'Clean Data'!N9:N58) -> 5040 | C46: =COUNTIF('Clean Data'!D9:D58,A46) -> 1 | D46: =SUMIF('Clean Data'!D9:D58,A46,'Clean Data'!F9:F58) -> 2
A47: Tshirt | B47: =SUMIF('Clean Data'!D10:D59,A47,'Clean Data'!N10:N59) -> 9547.5 | C47: =COUNTIF('Clean Data'!D10:D59,A47) -> 3 | D47: =SUMIF('Clean Data'!D10:D59,A47,'Clean Data'!F10:F59) -> 12
A48: Jeans | B48: =SUMIF('Clean Data'!D11:D60,A48,'Clean Data'!N11:N60) -> 9024 | C48: =COUNTIF('Clean Data'!D11:D60,A48) -> 2 | D48: =SUMIF('Clean Data'!D11:D60,A48,'Clean Data'!F11:F60) -> 5
A49: Watch | B49: =SUMIF('Clean Data'!D12:D61,A49,'Clean Data'!N12:N61) -> 18532 | C49: =COUNTIF('Clean Data'!D12:D61,A49) -> 3 | D49: =SUMIF('Clean Data'!D12:D61,A49,'Clean Data'!F12:F61) -> 5
A50: Bagpack | B50: =SUMIF('Clean Data'!D2:D51,A50,'Clean Data'!N2:N51) -> 3240 | C50: =COUNTIF('Clean Data'!D2:D51,A50) -> 1 | D50: =SUMIF('Clean Data'!D2:D51,A50,'Clean Data'!F2:F51) -> 2
A51: Power bank | B51: =SUMIF('Clean Data'!D14:D63,A51,'Clean Data'!N14:N63) -> 6164 | C51: =COUNTIF('Clean Data'!D14:D63,A51) -> 2 | D51: =SUMIF('Clean Data'!D14:D63,A51,'Clean Data'!F14:F63) -> 5
A57: Date | B57: Net sales
A58: 46235 | B58: =SUMIF('Clean Data'!B$2:B$51,A58,'Clean Data'!N$2:N$51) -> 81000
A59: 46236 | B59: =SUMIF('Clean Data'!B$2:B$51,A59,'Clean Data'!N$2:N$51) -> 2375
A60: 46237 | B60: =SUMIF('Clean Data'!B$2:B$51,A60,'Clean Data'!N$2:N$51) -> 25760
...

Sheet Dashboard 
B3: E-COMMERCE SALES DASHBOARD
B6: Metric | C6: Value
B7: Total orders | C7: ='Summary '!B7 -> 50
B8: Net sales | C8: ='Summary '!B11 -> 676263.5
B9: Total quantity | C9: ='Summary '!B8 -> 106
B10: Average order value | C10: ='Summary '!B12 -> 13525.27
